<mujoco model="ur5e">
  <!--
    UR5e model based on MuJoCo Menagerie (google-deepmind/mujoco_menagerie)
    with OBJ visual meshes from the official URDF description.
    License: BSD-3-Clause (ROS Industrial Consortium).

    Body/joint/site/actuator names are adapted to match this project's
    conventions (see core/collision.py, envs/*.py).
  -->
  <compiler angle="radian" meshdir="assets/ur5e" autolimits="true"/>
  <option timestep="0.002" gravity="0 0 -9.81" integrator="implicitfast"/>

  <visual>
    <quality shadowsize="4096"/>
    <map fogstart="8" fogend="12"/>
  </visual>

  <default>
    <default class="ur5e">
      <material specular="0.5" shininess="0.25"/>
      <joint axis="0 1 0" range="-6.28319 6.28319" armature="0.1"/>
      <general gaintype="fixed" biastype="affine"
               ctrlrange="-6.2831 6.2831"
               gainprm="800" biasprm="0 -800 -40"
               forcerange="-150 150"/>

      <default class="size3">
        <default class="size3_limited">
          <joint range="-3.1415 3.1415"/>
          <general ctrlrange="-3.1415 3.1415"/>
        </default>
      </default>
      <default class="size1">
        <general gainprm="200" biasprm="0 -200 -20"
                 forcerange="-28 28"/>
      </default>

      <default class="visual">
        <geom type="mesh" contype="0" conaffinity="0" group="2"/>
      </default>
      <default class="collision">
        <geom type="capsule" group="3" contype="1" conaffinity="1"/>
        <default class="eef_collision">
          <geom type="cylinder"/>
        </default>
      </default>

      <site size="0.001" rgba="0.5 0.5 0.5 0.3" group="4"/>
    </default>
  </default>

  <asset>
    <texture name="grid" type="2d" builtin="checker" width="256" height="256"
             rgb1="0.9 0.9 0.9" rgb2="0.8 0.8 0.8"/>
    <material name="tablemat" texture="grid" texrepeat="3 3" reflectance="0.05"/>

    <!-- UR colour palette (from Menagerie) -->
    <material class="ur5e" name="black"     rgba="0.033 0.033 0.033 1"/>
    <material class="ur5e" name="jointgray" rgba="0.278 0.278 0.278 1"/>
    <material class="ur5e" name="linkgray"  rgba="0.82  0.82  0.82  1"/>
    <material class="ur5e" name="urblue"    rgba="0.49  0.678 0.8   1"/>

    <!-- Visual meshes (OBJ converted from ROS-Industrial DAE) -->
    <mesh file="base_0.obj"/>
    <mesh file="base_1.obj"/>
    <mesh file="shoulder_0.obj"/>
    <mesh file="shoulder_1.obj"/>
    <mesh file="shoulder_2.obj"/>
    <mesh file="upperarm_0.obj"/>
    <mesh file="upperarm_1.obj"/>
    <mesh file="upperarm_2.obj"/>
    <mesh file="upperarm_3.obj"/>
    <mesh file="forearm_0.obj"/>
    <mesh file="forearm_1.obj"/>
    <mesh file="forearm_2.obj"/>
    <mesh file="forearm_3.obj"/>
    <mesh file="wrist1_0.obj"/>
    <mesh file="wrist1_1.obj"/>
    <mesh file="wrist1_2.obj"/>
    <mesh file="wrist2_0.obj"/>
    <mesh file="wrist2_1.obj"/>
    <mesh file="wrist2_2.obj"/>
    <mesh file="wrist3.obj"/>
  </asset>

  <!--
    UR5e DH parameters (from UR ROS2 Description):
      d1 = 0.1625 m    a2 = 0.425 m     a3 = 0.3922 m
      d4 = 0.1333 m    d5 = 0.0997 m    d6 = 0.0996 m
  -->

  <worldbody>
    <light pos="2 2 4" dir="-1 -1 -2"/>
    <geom name="table" type="box" pos="0 0 0.72" size="0.6 0.6 0.02"
          material="tablemat" rgba="0.84 0.78 0.68 1"/>
    <!-- Legs to make the table visually closer to Isaac Lab's table prop. -->
    <geom name="table_leg_fl" type="box" pos="0.52 0.52 0.36" size="0.03 0.03 0.36"
          rgba="0.35 0.35 0.35 1" friction="1 0.1 0.1"/>
    <geom name="table_leg_fr" type="box" pos="0.52 -0.52 0.36" size="0.03 0.03 0.36"
          rgba="0.35 0.35 0.35 1" friction="1 0.1 0.1"/>
    <geom name="table_leg_rl" type="box" pos="-0.52 0.52 0.36" size="0.03 0.03 0.36"
          rgba="0.35 0.35 0.35 1" friction="1 0.1 0.1"/>
    <geom name="table_leg_rr" type="box" pos="-0.52 -0.52 0.36" size="0.03 0.03 0.36"
          rgba="0.35 0.35 0.35 1" friction="1 0.1 0.1"/>
    <geom name="floor" type="plane" pos="0 0 0" size="4 4 0.1"
          rgba="0.9 0.9 0.9 1" friction="1 0.1 0.1"/>
    <camera name="top" pos="0.1 -0.3 2.5" xyaxes="1 0 0 0 1 0" mode="fixed"/>

    <!-- ================= UR5e Robot ================= -->
    <body name="base" pos="-0.30 0 0.74" quat="1 0 0 0" childclass="ur5e">
      <inertial mass="4.0" pos="0 0 0" diaginertia="0.00443 0.00443 0.0072"/>
      <geom mesh="base_0" material="black" class="visual" name="base_viz_0"/>
      <geom mesh="base_1" material="jointgray" class="visual" name="base_viz_1"/>
      <geom name="base_col" class="collision" size="0.06 0.06" pos="0 0 -0.04"/>

      <body name="shoulder" pos="0 0 0.163">
        <inertial mass="3.7" pos="0 0 0" diaginertia="0.0103 0.0103 0.00666"/>
        <joint name="shoulder_pan" class="size3" axis="0 0 1"/>
        <geom mesh="shoulder_0" material="urblue" class="visual" name="link1_viz_0"/>
        <geom mesh="shoulder_1" material="black" class="visual" name="link1_viz_1"/>
        <geom mesh="shoulder_2" material="jointgray" class="visual" name="link1_viz_2"/>
        <geom name="shoulder_col" class="collision" size="0.06 0.06" pos="0 0 -0.04"/>

        <body name="upper_arm" pos="0 0.138 0" quat="1 0 1 0">
          <inertial mass="8.393" pos="0 0 0.2125"
                    diaginertia="0.1339 0.1339 0.0151"/>
          <joint name="shoulder_lift" class="size3"/>
          <geom mesh="upperarm_0" material="linkgray" class="visual" name="link2_viz_0"/>
          <geom mesh="upperarm_1" material="black" class="visual" name="link2_viz_1"/>
          <geom mesh="upperarm_2" material="jointgray" class="visual" name="link2_viz_2"/>
          <geom mesh="upperarm_3" material="urblue" class="visual" name="link2_viz_3"/>
          <geom name="upper_arm_col_0" class="collision" pos="0 -0.04 0" quat="1 1 0 0" size="0.06 0.06"/>
          <geom name="upper_arm_col_1" class="collision" size="0.05 0.2" pos="0 0 0.2"/>

          <body name="forearm" pos="0 -0.131 0.425">
            <inertial mass="2.275" pos="0 0 0.196"
                      diaginertia="0.0312 0.0312 0.004095"/>
            <joint name="elbow" class="size3_limited"/>
            <geom mesh="forearm_0" material="urblue" class="visual" name="link3_viz_0"/>
            <geom mesh="forearm_1" material="linkgray" class="visual" name="link3_viz_1"/>
            <geom mesh="forearm_2" material="black" class="visual" name="link3_viz_2"/>
            <geom mesh="forearm_3" material="jointgray" class="visual" name="link3_viz_3"/>
            <geom name="forearm_col_0" class="collision" pos="0 0.08 0" quat="1 1 0 0" size="0.055 0.06"/>
            <geom name="forearm_col_1" class="collision" size="0.038 0.19" pos="0 0 0.2"/>

            <body name="wrist1" pos="0 0 0.392" quat="1 0 1 0">
              <inertial mass="1.219" pos="0 0.127 0"
                        diaginertia="0.00256 0.00256 0.00219"/>
              <joint name="wrist1" class="size1"/>
              <geom mesh="wrist1_0" material="black" class="visual" name="link4_viz_0"/>
              <geom mesh="wrist1_1" material="urblue" class="visual" name="link4_viz_1"/>
              <geom mesh="wrist1_2" material="jointgray" class="visual" name="link4_viz_2"/>
              <geom name="wrist1_col" class="collision" pos="0 0.05 0" quat="1 1 0 0" size="0.04 0.07"/>

              <body name="wrist2" pos="0 0.127 0">
                <inertial mass="1.219" pos="0 0 0.1"
                          diaginertia="0.00256 0.00256 0.00219"/>
                <joint name="wrist2" axis="0 0 1" class="size1"/>
                <geom mesh="wrist2_0" material="black" class="visual" name="link5_viz_0"/>
                <geom mesh="wrist2_1" material="urblue" class="visual" name="link5_viz_1"/>
                <geom mesh="wrist2_2" material="jointgray" class="visual" name="link5_viz_2"/>
                <geom name="wrist2_col_0" class="collision" size="0.04 0.06" pos="0 0 0.04"/>
                <geom name="wrist2_col_1" class="collision" pos="0 0.02 0.1" quat="1 1 0 0" size="0.04 0.04"/>

                <body name="wrist3" pos="0 0 0.1">
                  <inertial mass="0.1889" pos="0 0.0772 0" quat="1 0 0 1"
                            diaginertia="0.000132 9.91e-05 9.91e-05"/>
                  <joint name="wrist3" class="size1"/>
                  <geom material="linkgray" mesh="wrist3" class="visual" name="link6_viz"/>
                  <geom name="wrist3_col" class="eef_collision" pos="0 0.08 0" quat="1 1 0 0" size="0.04 0.02"/>

                  <!-- End-effector camera (moves with the tool flange) -->
                  <camera name="ee_cam" pos="0 0.14 0" xyaxes="1 0 0 0 0 1"
                          fovy="60" mode="fixed"/>

                  <!-- End-effector site and sphere (project convention) -->
                  <site name="ee_site" pos="0 0.1 0" quat="-1 1 0 0" size="0.01"
                        rgba="0.1 0.8 0.2 1"/>
                  <geom name="ee_sphere" type="sphere" pos="0 0.1 0"
                        size="0.02" rgba="0.1 0.8 0.2 0.6"
                        contype="0" conaffinity="0"/>
                </body>
              </body>
            </body>
          </body>
        </body>
      </body>
    </body>
  </worldbody>

  <actuator>
    <general class="size3" name="shoulder_pan_motor" joint="shoulder_pan"/>
    <general class="size3" name="shoulder_lift_motor" joint="shoulder_lift"/>
    <general class="size3_limited" name="elbow_motor" joint="elbow"/>
    <general class="size1" name="wrist1_motor" joint="wrist1"/>
    <general class="size1" name="wrist2_motor" joint="wrist2"/>
    <general class="size1" name="wrist3_motor" joint="wrist3"/>
  </actuator>

  <keyframe>
    <key name="home"
         qpos="-0.2670 -1.5708 1.5708 -1.5708 -1.5708 0"
         ctrl="-0.2670 -1.5708 1.5708 -1.5708 -1.5708 0"/>
  </keyframe>
</mujoco>
